第12章：JavaScript中的错误处理与调试

在本章中，我们将探讨 JavaScript 中的错误处理和调试技术。作为开发者，遇到错误和 bug 是开发过程中的常见部分。能够有效地处理错误并调试代码，对于构建健壮且可靠的 JavaScript 应用程序至关重要。

12.1 理解 JavaScript 中的错误

JavaScript 中的错误可能由于各种原因发生，例如语法错误、逻辑错误或运行时异常。当错误发生时，它可能会中断代码的正常执行流程，并可能导致应用程序崩溃。

JavaScript 提供了内置的错误对象，如 `SyntaxError`、`TypeError` 和 `ReferenceError`，用来表示不同类型的错误。这些错误对象包含有用的信息，包括错误消息和堆栈跟踪，有助于确定错误的来源。

12.2 使用 try...catch 处理错误

`try...catch` 语句用于处理 JavaScript 中的错误。它允许我们将一段代码包裹在 `try` 块中，并指定一个 `catch` 块，在 `try` 块中发生错误时执行。

这是一个例子：

```jsjavascript

try {

// Code that might throw an error

const result = someFunction();

console.log(result);

} catch (error) {

// Code to handle the error

console.log('An error occurred:', error.message);

}

```

在这个例子中，`try` 块包含可能抛出错误的代码。如果发生错误，它将被 `catch` 块捕获，我们可以相应地处理它。`catch` 块中的 `error` 参数代表错误对象。

通过使用 `try...catch`，我们可以优雅地处理错误，防止它们导致应用程序崩溃。我们还可以提供回退行为或向用户显示有意义的错误信息。

12.3 抛出自定义错误

除了内置的错误对象，JavaScript 还允许我们使用 `throw` 语句创建自定义错误对象。自定义错误可以提供更具体的错误信息，有助于调试。

这是一个抛出自定义错误的例子：

```jsjavascript

function divide(a, b) {

if (b === 0) {

throw new Error('Division by zero is not allowed.');

}

return a / b;

}

try {

const result = divide(10, 0);

console.log(result);

} catch (error) {

console.log('An error occurred:', error.message);

}

```

在这个例子中，`divide` 函数检查除数（`b`）是否为零。如果是，它会抛出一个自定义的 `Error` 对象，并附带描述性的错误信息。然后，该错误会在 `catch` 块中被捕获和处理。

通过抛出自定义错误，我们可以提供关于异常情况的更多有意义的信息，并指导调试过程。

12.4 调试技巧

调试是识别和修复代码中的 bug 的过程。JavaScript 提供了多种工具和技术来帮助调试。常用的一些技巧包括：

- Console.log：在代码中的关键位置放置 `console.log` 语句，可以让我们在运行时输出值或消息到控制台以供检查。

- 中断点：现代网页浏览器提供了内置调试器的开发者工具。通过在特定的代码行设置中断点，我们可以暂停执行并检查变量的状态，逐步执行代码，分析执行流程。

- 调试工具：开发者工具还提供了一系列调试功能，例如检查调用栈、监控网络请求、分析内存使用情况以及性能分析。

- 错误信息：关注控制台中显示的错误信息可以为我们提供关于错误原因的宝贵线索。错误信息通常包含关于错误类型、错误发生的特定代码行以及其他有助于定位问题的详细信息。

- 代码审查：请同事或同行审查我们的代码可以提供新的视角，并识别我们可能忽视的潜在问题。

- 橡皮鸭调试法：将我们的代码和正在解决的问题解释给一个无生命的物体（如橡皮鸭），可以帮助我们发现逻辑错误或找到替代解决方案。将问题语言化的过程通常会带来新的见解和发现。

通过利用这些调试技巧，我们可以有效地识别并解决JavaScript代码中的错误，从而构建出更可靠、稳定的应用程序。

12.5 处理异步错误

JavaScript通常涉及异步操作，例如进行网络请求或访问数据库中的数据。处理异步代码中的错误需要采取不同的方法。

一种常见的方法是使用承诺（promises）和`catch`方法来处理错误：

```jsjavascript

async function fetchData() {

try {

const response = await fetch('https://api.example.com/data');

const data = await response.json();

// Process the data

} catch (error) {

console.log('An error occurred:', error.message);

}

}

fetchData();

```

在这个示例中，我们定义了一个`async`函数`fetchData`，该函数使用`fetch` API进行异步网络请求。我们使用`await`等待响应和解析后的数据。如果请求或解析过程中发生错误，它将在`catch`块中被捕获。

通过利用承诺（promises）和`catch`方法，我们可以处理异步操作中的错误，确保我们的代码能够优雅地处理任何潜在问题。

12.6 结论

错误处理和调试是JavaScript开发者必备的技能。通过理解如何使用`try...catch`处理错误、抛出自定义错误以及采用有效的调试技巧，我们可以更高效地诊断和修复代码中的错误。

在本章中，我们探讨了如何使用`try...catch`进行错误处理、抛出自定义错误以及各种调试技巧，如控制台日志、断点调试以及使用开发者工具。我们还讨论了如何使用承诺（promises）和`catch`方法处理异步代码中的错误。

通过掌握错误处理和调试技巧，我们可以创建更强健的JavaScript应用程序，减少错误发生的可能性，并为用户提供更好的体验。
